Workbook

Sheet Pengujian_100_Sampel
A1: IDENTITAS KUERI & DOKUMEN MEDIS UJI | G1: 1. EXACT MATCH (BASELINE DETERMINISTIK) | L1: 2. N-GRAM (BI-GRAM EXPANSION, theta = 0.40) | Q1: 3. LSH (MINHASH k = 3, FILTER tau = 85%) | V1: UJI BERPASANGAN
A2: No | B2: Doc ID | C2: Kata Asli | D2: Kueri Typo | E2: Kategori Typo | F2: Diagnosis ICD-10 (Deskripsi) | G2: Waktu (ms) | H2: Recall (%) | I2: Kandidat Server | J2: Lolos Filter | K2: False Positive | L2: Waktu (ms) | M2: Recall (%) | N2: Kandidat Server | O2: Lolos Filter | P2: False Positive | Q2: Waktu (ms) | R2: Recall (%) | S2: Kandidat Server | T2: Lolos Filter | U2: False Positive | V2: Selisih N-Gram - LSH (ms)
A3: 1 | B3: D04.5 | C3: carcinoma | D3: carcinoa | E3: Omission | F3: Carcinoma in situ of skin of trunk | G3: 1.91 | H3: 0 | I3: 0 | J3: 0 | K3: 0 | L3: 266.64 | M3: 100 | N3: 5497 | O3: 50 | P3: 49 | Q3: 181.54 | R3: 100 | S3: 7414 | T3: 50 | U3: 49 | V3: =L3-Q3 -> 85.1
A4: 2 | B4: Y87.0 | C4: sequelae | D4: sequgelae | E4: Insertion | F4: Sequelae of intentional self-harm | G4: 2.08 | H4: 0 | I4: 0 | J4: 0 | K4: 0 | L4: 227.99 | M4: 100 | N4: 4775 | O4: 89 | P4: 88 | Q4: 83.42 | R4: 100 | S4: 3544 | T4: 89 | U4: 88 | V4: =L4-Q4 -> 144.57
A5: 3 | B5: V37.0 | C5: occupant | D5: oecupant | E5: Substitution | F5: Occupant of three-wheeled motor vehicle injured in collision with fixed or stationary object, driver nontraffic accident | G5: 1.47 | H5: 0 | I5: 0 | J5: 0 | K5: 0 | L5: 244.39 | M5: 100 | N5: 5628 | O5: 479 | P5: 478 | Q5: 203.17 | R5: 100 | S5: 6030 | T5: 479 | U5: 478 | V5: =L5-Q5 -> 41.22
A6: 4 | B6: M77.1 | C6: lateral | D6: laetral | E6: Transposition | F6: Lateral epicondylitis | G6: 3.06 | H6: 0 | I6: 0 | J6: 0 | K6: 0 | L6: 388.17 | M6: 100 | N6: 5777 | O6: 8 | P6: 7 | Q6: 109.71 | R6: 100 | S6: 4236 | T6: 8 | U6: 7 | V6: =L6-Q6 -> 278.46
A7: 5 | B7: C91.4 | C7: leukaemia | D7: leukamia | E7: Omission | F7: Hairy-cell leukaemia | G7: 1.73 | H7: 0 | I7: 0 | J7: 0 | K7: 0 | L7: 239.94 | M7: 100 | N7: 4051 | O7: 31 | P7: 30 | Q7: 73.54 | R7: 100 | S7: 2672 | T7: 31 | U7: 30 | V7: =L7-Q7 -> 166.4
A8: 6 | B8: P58.5 | C8: neonatal | D8: nceonatal | E8: Insertion | F8: Neonatal jaundice due to swallowed maternal blood | G8: 1.9 | H8: 0 | I8: 0 | J8: 0 | K8: 0 | L8: 272.81 | M8: 100 | N8: 5813 | O8: 66 | P8: 65 | Q8: 96.06 | R8: 100 | S8: 4401 | T8: 66 | U8: 65 | V8: =L8-Q8 -> 176.75
A9: 7 | B9: E52 | C9: niacin | D9: niecin | E9: Substitution | F9: Niacin deficiency [pellagra] | G9: 1.89 | H9: 0 | I9: 0 | J9: 0 | K9: 0 | L9: 275.22 | M9: 0 | N9: 7124 | O9: 0 | P9: 0 | Q9: 125.72 | R9: 0 | S9: 5923 | T9: 0 | U9: 0 | V9: =L9-Q9 -> 149.5
A10: 8 | B10: H19.2 | C10: keratitis | D10: keraittis | E10: Transposition | F10: Keratitis and keratoconjunctivitis in other infectious and parasitic diseases classified elsewhere | G10: 1.48 | H10: 0 | I10: 0 | J10: 0 | K10: 0 | L10: 369 | M10: 100 | N10: 8028 | O10: 7 | P10: 6 | Q10: 148.35 | R10: 100 | S10: 6685 | T10: 7 | U10: 6 | V10: =L10-Q10 -> 220.65
A11: 9 | B11: Q82.2 | C11: mastocytosis | D11: mastcytosis | E11: Omission | F11: Mastocytosis | G11: 1.66 | H11: 0 | I11: 0 | J11: 0 | K11: 0 | L11: 277.2 | M11: 100 | N11: 5554 | O11: 1 | P11: 0 | Q11: 130.11 | R11: 100 | S11: 6009 | T11: 1 | U11: 0 | V11: =L11-Q11 -> 147.09
A12: 10 | B12: T33.9 | C12: superficial | D12: superfoicial | E12: Insertion | F12: Superficial frostbite of other and unspecified sites | G12: 2.07 | H12: 0 | I12: 0 | J12: 0 | K12: 0 | L12: 338.34 | M12: 100 | N12: 5359 | O12: 71 | P12: 70 | Q12: 28.1 | R12: 100 | S12: 1332 | T12: 71 | U12: 70 | V12: =L12-Q12 -> 310.24
A13: 11 | B13: M54.6 | C13: thoracic | D13: thorauic | E13: Substitution | F13: Pain in thoracic spine | G13: 1.61 | H13: 0 | I13: 0 | J13: 0 | K13: 0 | L13: 210.51 | M13: 100 | N13: 4399 | O13: 20 | P13: 19 | Q13: 72.24 | R13: 100 | S13: 3445 | T13: 20 | U13: 19 | V13: =L13-Q13 -> 138.27
A14: 12 | B14: Q54.9 | C14: hypospadias | D14: hpyospadias | E14: Transposition | F14: Hypospadias, unspecified | G14: 1.55 | H14: 0 | I14: 0 | J14: 0 | K14: 0 | L14: 223.84 | M14: 100 | N14: 4006 | O14: 6 | P14: 5 | Q14: 80.22 | R14: 100 | S14: 3185 | T14: 6 | U14: 5 | V14: =L14-Q14 -> 143.62
... A102: 100 | B102: N03.0 | C102: chronic | D102: chrnoic | E102: Transposition | F102: Chronic nephritic syndrome, minor glomerular abnormality | G102: 1.25 | H102: 0 | I102: 0 | J102: 0 | K102: 0 | L102: 104.83 | M102: 100 | N102: 1886 | O102: 168 | P102: 167 | Q102: 40.99 | R102: 100 | S102: 1740 | T102: 168 | U102: 167 | V102: =L102-Q102 -> 63.84
E105: TABLE 7. PARAMETER STATISTIK & UJI HIPOTESIS LATENSI KOMPUTASI (PAIRED T-TEST, n = 100)
E106: Parameter Statistik (Latensi Komputasi) | G106: Exact Match (ms) | L106: N-Gram (ms) | Q106: LSH MinHash (ms) | T106: Keterangan Rumus / Penjelasan Matematis
E107: Mean (Rata-rata Latensi μ) | G107: =AVERAGE(G3:G102) -> 1.5069 | L107: =AVERAGE(L3:L102) -> 248.4308 | Q107: =AVERAGE(Q3:Q102) -> 74.5818 | T107: Rata-rata aritmatika total latensi round-trip 100 kueri
E108: Standar Deviasi Sampel (s) | G108: =_xlfn.STDEV.S(G3:G102) -> 0.37391107 | L108: =_xlfn.STDEV.S(L3:L102) -> 66.198571 | Q108: =_xlfn.STDEV.S(Q3:Q102) -> 125.09266 | T108: Deviasi standar sampel (rumus STDEV.S Excel)
E109: Varians Sampel (s²) | G109: =_xlfn.VAR.S(G3:G102) -> 0.13980948 | L109: =_xlfn.VAR.S(L3:L102) -> 4382.2508 | Q109: =_xlfn.VAR.S(Q3:Q102) -> 15648.173 | T109: Variansi sampel (kuadrat deviasi standar)
E110: Jumlah Observasi (N) | G110: =COUNT(G3:G102) -> 100 | L110: =COUNT(L3:L102) -> 100 | Q110: =COUNT(Q3:Q102) -> 100 | T110: Total kueri uji klinis berpasangan (paired)
E111: Margin of Error (95% CI) = nilai ± di Table 8 | G111: =ROUND(_xlfn.T.INV.2T(0.05,G110-1),3)*(G108/SQRT(G110)) -> 0.074183955 | L111: =ROUND(_xlfn.T.INV.2T(0.05,L110-1),3)*(L108/SQRT(L110)) -> 13.133796 | Q111: =ROUND(_xlfn.T.INV.2T(0.05,Q110-1),3)*(Q108/SQRT(Q110)) -> 24.818383 | T111: t_crit * (s / √n); t_crit = T.INV.2T(0.05; n-1) dibulatkan 3 desimal = 1.984 (df = 99, α = 0.05), sama dengan t_crit yang tercetak di Table 7
E112: 95% CI Lower Bound | G112: =G107-G111 -> 1.432716 | L112: =L107-L111 -> 235.297 | Q112: =Q107-Q111 -> 49.763417 | T112: Batas bawah interval kepercayaan 95% (Mean - Margin of Error)
E113: 95% CI Upper Bound | G113: =G107+G111 -> 1.581084 | L113: =L107+L111 -> 261.5646 | Q113: =Q107+Q111 -> 99.400183 | T113: Batas atas interval kepercayaan 95% (Mean + Margin of Error)
E114: Mean Difference (D̄ = μ_Ngram - μ_LSH) | L114: =L107-Q107 -> 173.849 | T114: Selisih penghematan rata-rata latensi LSH terhadap N-Gram
E115: Pearson Correlation (r) | L115: =CORREL(L3:L102, Q3:Q102) -> 0.19590976 | T115: Korelasi linier kueri berpasangan N-Gram dan LSH
E116: Degrees of Freedom (df = N - 1) | L116: =L110-1 -> 99 | T116: Derajat kebebasan pengujian berpasangan (paired degrees of freedom)
E117: t-statistic (t_calc) | L117: =AVERAGE(V3:V102)/(_xlfn.STDEV.S(V3:V102)/SQRT(COUNT(V3:V102))) -> 13.41842 | T117: t = rata-rata selisih / (SD selisih / √n), dihitung dari kolom V (bukan angka ketikan)
E118: P-Value (Two-Tailed) | L118: =_xlfn.T.TEST(L3:L102, Q3:Q102, 2, 1) | T118: Uji t berpasangan dua arah (T.TEST tipe 1 paired, tail 2)
E119: Keputusan Statistik (alpha = 0.05) | L119: Reject H0 (p < 0.001) | T119: Keunggulan latensi LSH terbukti signifikan secara statistik
E120: t kritis (two-tailed, α = 0.05) | L120: =_xlfn.T.INV.2T(0.05,L110-1) -> 1.984217 | T120: Nilai t_crit di Table 7 naskah (1.984)
E121: Teks Table 8 naskah: Latensi (Mean ± Margin of Error 95%) | G121: =TEXT(G107,"0.00")&" ± "&TEXT(G111,"0.00") -> 1.51 ± 0.07 | L121: =TEXT(L107,"0.00")&" ± "&TEXT(L111,"0.00") -> 248.43 ± 13.13 | Q121: =TEXT(Q107,"0.00")&" ± "&TEXT(Q111,"0.00") -> 74.58 ± 24.82 | T121: Angka sesudah ± di Table 8 adalah MARGIN OF ERROR CI 95% (= t_crit·s/√n), bukan standar deviasi. Contoh LSH: 1.984 × 125.09 / √100 = 24.82
E122: Pembanding: Mean ± Standar Deviasi (s) | G122: =TEXT(G107,"0.00")&" ± "&TEXT(G108,"0.00") -> 1.51 ± 0.37 | L122: =TEXT(L107,"0.00")&" ± "&TEXT(L108,"0.00") -> 248.43 ± 66.20 | Q122: =TEXT(Q107,"0.00")&" ± "&TEXT(Q108,"0.00") -> 74.58 ± 125.09 | T122: Bukan format yang dipakai di Table 8; ditampilkan agar perbedaan SD vs margin of error jelas (SD ada di Table 7)
E123: Kontrol kualitas: jumlah latensi negatif | G123: =COUNTIF(G3:G102,"<0") -> 0 | L123: =COUNTIF(L3:L102,"<0") -> 0 | Q123: =COUNTIF(Q3:Q102,"<0") -> 2 | T123: Latensi tidak mungkin negatif. Nilai negatif (sel merah) berasal dari timer microtime() yang mundur saat run; dibiarkan apa adanya, bukan diedit
E126: TABLE 8 & FIGURE 7. RINGKASAN METRIK KLASIFIKASI & RETRIEVAL PASCA CLIENT FILTERING (tau = 85%)
E127: Metrik Evaluasi & Deskripsi | G127: Exact Match | L127: N-Gram (theta = 0.40) | Q127: LSH MinHash (k = 3) | T127: Keterangan Rumus / Penjelasan Sumber Data
E128: True Positives (TP) [Target Ditemukan] | G128: =COUNTIF(H3:H102, 100) -> 0 | L128: =COUNTIF(M3:M102, 100) -> 91 | Q128: =COUNTIF(R3:R102, 100) -> 88 | T128: Jumlah kueri di mana dokumen target berhasil ditemukan (Recall = 100%)
E129: False Negatives (FN) [Target Terlewat] | G129: =COUNTIF(H3:H102, 0) -> 100 | L129: =COUNTIF(M3:M102, 0) -> 9 | Q129: =COUNTIF(R3:R102, 0) -> 12 | T129: Jumlah kueri di mana dokumen target gagal ditemukan (Recall = 0%)
E130: Total False Positives (FP) [Akumulasi Lolos Klien] | G130: =SUM(K3:K102) -> 0 | L130: =SUM(P3:P102) -> 16260 | Q130: =SUM(U3:U102) -> 15958 | T130: Akumulasi total dokumen bukan-target yang tidak sengaja lolos penyaringan klien
E131: Search Recall (%) | G131: =AVERAGE(H3:H102) -> 0 | L131: =AVERAGE(M3:M102) -> 91 | Q131: =AVERAGE(R3:R102) -> 88 | T131: Rumus: TP / (TP + FN) * 100% atau rata-rata kolom Recall 100 kueri
...

Sheet Analisis_Sensitivitas
A1: FIGURE 8. ANALISIS SENSITIVITAS MULTI-PARAMETER ALGORITMA (k, tau, theta)
A3: 1. PENGARUH DIMENSI MINHASH (k) TERHADAP RECALL, LATENSI, DAN KANDIDAT (tau = 85%) [Fig. 8a]
A4: k (Bands) | B4: Rata-rata Latensi (ms) | C4: Standar Deviasi (ms) | D4: Rata-rata Kandidat Server | E4: Recall (%) | F4: Precision (%)
A5: 2 | B5: 52.76 | C5: 119.34 | D5: 3102.07 | E5: 76 | F5: 0.58
A6: 3 | B6: 91.66 | C6: 41.73 | D6: 4018.16 | E6: 88 | F6: 0.55
A7: 4 | B7: 117.08 | C7: 47.98 | D7: 5005.64 | E7: 90 | F7: 0.55
A8: 5 | B8: 131.32 | C8: 126.74 | D8: 6034.51 | E8: 90 | F8: 0.55
A11: 2. PENGARUH AMBANG BATAS KESAMAAN KLIEN (tau) TERHADAP RECALL DAN PRECISION (k = 3) [Fig. 8b]
A12: Ambang Batas tau (%) | B12: Rata-rata Latensi (ms) | C12: Recall (%) | D12: Precision (%) | E12: Keterangan Analitis
A13: 70% | B13: 70.74 | C13: 96 | D13: 0.47 | E13: Recall sangat tinggi, namun meloloskan banyak noise kandidat non-target
A14: 75% | B14: 83.36 | C14: 96 | D14: 0.52 | E14: Penyaringan false positive mulai membaik, recall tetap terjaga tinggi
A15: 80% | B15: 50.54 | C15: 96 | D15: 0.55 | E15: Zona transisi toleransi kesalahan klinis yang stabil
A16: 85% | B16: 60.66 | C16: 88 | D16: 0.55 | E16: Titik kompromi optimal (Recommended): Recall 88% dengan 96% false positive dipangkas
A17: 90% | B17: 61.95 | C17: 59 | D17: 0.64 | E17: Threshold terlalu ketat: Recall anjlok karena banyak typo klinis ditolak filter
A18: 95% | B18: 62.09 | C18: 17 | D18: 0.37 | E18: Kegagalan toleransi typo: Hanya kueri yang hampir identik yang diloloskan filter klien
A21: 3. PENGARUH HIT-RATIO N-GRAM (theta) TERHADAP KANDIDAT CLOUD DAN LATENSI
A22: Ambang Batas theta | B22: Rata-rata Latensi (ms) | C22: Rata-rata Kandidat Server | D22: Recall (%)
A23: 0.3 | B23: 226.54 | C23: 6069.43 | D23: 91
A24: 0.4 | B24: 250.28 | C24: 4970.43 | D24: 91
A25: 0.5 | B25: 221.8 | C25: 4123.02 | D25: 91
A26: 0.6 | B26: 231.7 | C26: 3153.29 | D26: 91

Sheet Proyeksi_Skalabilitas
A1: FIGURE 9 (SECTION 3.5). ANALYTICAL SCALABILITY PROJECTION CALIBRATED ON OBSERVED ICD-10 DENSITY
A2: Kalibrasi Densitas Dasar (10.469 Dokumen): Exact = 10.51 baris/doc, N-Gram = 83.99 baris/doc, LSH k=3 = 31.55 baris/doc, LSH k=5 = 52.58 baris/doc (128 bytes/row)
A4: Jumlah Rekam Medis (Dokumen N) | B4: Baris Indeks Exact | C4: Storage Exact (MB) | D4: Baris Indeks N-Gram | E4: Storage N-Gram (MB) | F4: Baris Indeks LSH (k=3) | G4: Storage LSH k=3 (MB) | H4: Baris Indeks LSH (k=5) | I4: Storage LSH k=5 (MB) | J4: Efisiensi Storage LSH vs N-Gram (%)
A5: 10469 | B5: 110102 | C5: =(B5*128)/(1024*1024) -> 13.440186 | D5: 879327 | E5: =(D5*128)/(1024*1024) -> 107.33972 | F5: 330306 | G5: =(F5*128)/(1024*1024) -> 40.320557 | H5: 550510 | I5: =(H5*128)/(1024*1024) -> 67.200928 | J5: =(D5-F5)/D5 -> 0.624365
A6: 50000 | B6: =ROUND(110102*(A6/10469), 0) -> 525848 | C6: =(B6*128)/(1024*1024) -> 64.19043 | D6: =ROUND(879327*(A6/10469), 0) -> 4199670 | E6: =(D6*128)/(1024*1024) -> 512.65503 | F6: =ROUND(330306*(A6/10469), 0) -> 1577543 | G6: =(F6*128)/(1024*1024) -> 192.57117 | H6: =ROUND(550510*(A6/10469), 0) -> 2629239 | I6: =(H6*128)/(1024*1024) -> 320.95203 | J6: =(D6-F6)/D6 -> 0.62436501
A7: 100000 | B7: =ROUND(110102*(A7/10469), 0) -> 1051695 | C7: =(B7*128)/(1024*1024) -> 128.38074 | D7: =ROUND(879327*(A7/10469), 0) -> 8399341 | E7: =(D7*128)/(1024*1024) -> 1025.3102 | F7: =ROUND(330306*(A7/10469), 0) -> 3155086 | G7: =(F7*128)/(1024*1024) -> 385.14233 | H7: =ROUND(550510*(A7/10469), 0) -> 5258477 | I7: =(H7*128)/(1024*1024) -> 641.90393 | J7: =(D7-F7)/D7 -> 0.62436505
A8: 250000 | B8: =ROUND(110102*(A8/10469), 0) -> 2629239 | C8: =(B8*128)/(1024*1024) -> 320.95203 | D8: =ROUND(879327*(A8/10469), 0) -> 20998352 | E8: =(D8*128)/(1024*1024) -> 2563.2754 | F8: =ROUND(330306*(A8/10469), 0) -> 7887716 | G8: =(F8*128)/(1024*1024) -> 962.85596 | H8: =ROUND(550510*(A8/10469), 0) -> 13146194 | I8: =(H8*128)/(1024*1024) -> 1604.76 | J8: =(D8-F8)/D8 -> 0.624365
A9: 500000 | B9: =ROUND(110102*(A9/10469), 0) -> 5258477 | C9: =(B9*128)/(1024*1024) -> 641.90393 | D9: =ROUND(879327*(A9/10469), 0) -> 41996705 | E9: =(D9*128)/(1024*1024) -> 5126.5509 | F9: =ROUND(330306*(A9/10469), 0) -> 15775432 | G9: =(F9*128)/(1024*1024) -> 1925.7119 | H9: =ROUND(550510*(A9/10469), 0) -> 26292387 | I9: =(H9*128)/(1024*1024) -> 3209.5199 | J9: =(D9-F9)/D9 -> 0.62436501
A10: 1000000 | B10: =ROUND(110102*(A10/10469), 0) -> 10516955 | C10: =(B10*128)/(1024*1024) -> 1283.808 | D10: =ROUND(879327*(A10/10469), 0) -> 83993409 | E10: =(D10*128)/(1024*1024) -> 10253.102 | F10: =ROUND(330306*(A10/10469), 0) -> 31550864 | G10: =(F10*128)/(1024*1024) -> 3851.4238 | H10: =ROUND(550510*(A10/10469), 0) -> 52584774 | I10: =(H10*128)/(1024*1024) -> 6419.0398 | J10: =(D10-F10)/D10 -> 0.624365

Sheet Diversitas_Kueri_Tabel9
A1: TABLE 9 (SECTION 3.4). EVALUASI DIVERSITAS KUERI KLINIS & STRATIFIKASI LINGUISTIK/KESALAHAN
A3: RINGKASAN STRATIFIKASI BERDASARKAN 5 DIMENSI DIVERSITAS KUERI (FORMULA NATIVE DARI DATA DI BAWAH)
A4: Dimensi Diversitas Kueri | B4: Jumlah Sampel (n) | C4: Recall Exact (%) | D4: Recall N-Gram (%) | E4: Recall LSH (%) | F4: Latensi N-Gram (ms) | G4: Latensi LSH (ms) | H4: Efisiensi Latensi LSH (%) | I4: SD N-Gram (ms) | J4: SD LSH (ms) | K4: Teks Table 9: N-Gram (Mean ± SD) | L4: Teks Table 9: LSH (Mean ± SD) | M4: Paired t | N4: df
A5: Short Terms (4-6 chars) | B5: =COUNT(H16:H35) -> 20 | C5: =AVERAGE(I16:I35) -> 0 | D5: =AVERAGE(K16:K35) -> 70 | E5: =AVERAGE(M16:M35) -> 60 | F5: =AVERAGE(J16:J35) -> 151.871 | G5: =AVERAGE(L16:L35) -> 81.2645 | H5: =(F5-G5)/F5 -> 0.46491101 | I5: =_xlfn.STDEV.S(J16:J35) -> 46.231166 | J5: =_xlfn.STDEV.S(L16:L35) -> 61.555347 | K5: =TEXT(F5,"0.00")&" ± "&TEXT(I5,"0.0") -> 151.87 ± 46.2 | L5: =TEXT(G5,"0.00")&" ± "&TEXT(J5,"0.0") -> 81.26 ± 61.6 | M5: =AVERAGE(N16:N35)/(_xlfn.STDEV.S(N16:N35)/SQRT(COUNT(N16:N35))) -> 5.6576762 | N5: =COUNT(N16:N35)-1 -> 19
A6: Medium Terms (7-10 chars) | B6: =COUNT(H36:H55) -> 20 | C6: =AVERAGE(I36:I55) -> 0 | D6: =AVERAGE(K36:K55) -> 95 | E6: =AVERAGE(M36:M55) -> 95 | F6: =AVERAGE(J36:J55) -> 197.096 | G6: =AVERAGE(L36:L55) -> 81.303 | H6: =(F6-G6)/F6 -> 0.58749543 | I6: =_xlfn.STDEV.S(J36:J55) -> 67.141829 | J6: =_xlfn.STDEV.S(L36:L55) -> 37.710544 | K6: =TEXT(F6,"0.00")&" ± "&TEXT(I6,"0.0") -> 197.10 ± 67.1 | L6: =TEXT(G6,"0.00")&" ± "&TEXT(J6,"0.0") -> 81.30 ± 37.7 | M6: =AVERAGE(N36:N55)/(_xlfn.STDEV.S(N36:N55)/SQRT(COUNT(N36:N55))) -> 7.7189164 | N6: =COUNT(N36:N55)-1 -> 19
A7: Long Polysyllabic (>=11 chars) | B7: =COUNT(H56:H75) -> 20 | C7: =AVERAGE(I56:I75) -> 0 | D7: =AVERAGE(K56:K75) -> 100 | E7: =AVERAGE(M56:M75) -> 100 | F7: =AVERAGE(J56:J75) -> 252.581 | G7: =AVERAGE(L56:L75) -> 79.434 | H7: =(F7-G7)/F7 -> 0.68551079 | I7: =_xlfn.STDEV.S(J56:J75) -> 67.067629 | J7: =_xlfn.STDEV.S(L56:L75) -> 33.976867 | K7: =TEXT(F7,"0.00")&" ± "&TEXT(I7,"0.0") -> 252.58 ± 67.1 | L7: =TEXT(G7,"0.00")&" ± "&TEXT(J7,"0.0") -> 79.43 ± 34.0 | M7: =AVERAGE(N56:N75)/(_xlfn.STDEV.S(N56:N75)/SQRT(COUNT(N56:N75))) -> 11.772629 | N7: =COUNT(N56:N75)-1 -> 19
A8: Compound Typo (Edit Distance d=2) | B8: =COUNT(H76:H95) -> 20 | C8: =AVERAGE(I76:I95) -> 0 | D8: =AVERAGE(K76:K95) -> 35 | E8: =AVERAGE(M76:M95) -> 35 | F8: =AVERAGE(J76:J95) -> 182.854 | G8: =AVERAGE(L76:L95) -> 73.36 | H8: =(F8-G8)/F8 -> 0.5988056 | I8: =_xlfn.STDEV.S(J76:J95) -> 65.645381 | J8: =_xlfn.STDEV.S(L76:L95) -> 33.435523 | K8: =TEXT(F8,"0.00")&" ± "&TEXT(I8,"0.0") -> 182.85 ± 65.6 | L8: =TEXT(G8,"0.00")&" ± "&TEXT(J8,"0.0") -> 73.36 ± 33.4 | M8: =AVERAGE(N76:N95)/(_xlfn.STDEV.S(N76:N95)/SQRT(COUNT(N76:N95))) -> 8.76876 | N8: =COUNT(N76:N95)-1 -> 19
A9: Phonetic/Orthographic Shifts | B9: =COUNT(H96:H115) -> 20 | C9: =AVERAGE(I96:I115) -> 0 | D9: =AVERAGE(K96:K115) -> 25 | E9: =AVERAGE(M96:M115) -> 25 | F9: =AVERAGE(J96:J115) -> 201.4035 | G9: =AVERAGE(L96:L115) -> 86.347 | H9: =(F9-G9)/F9 -> 0.57127359 | I9: =_xlfn.STDEV.S(J96:J115) -> 71.393056 | J9: =_xlfn.STDEV.S(L96:L115) -> 39.127973 | K9: =TEXT(F9,"0.00")&" ± "&TEXT(I9,"0.0") -> 201.40 ± 71.4 | L9: =TEXT(G9,"0.00")&" ± "&TEXT(J9,"0.0") -> 86.35 ± 39.1 | M9: =AVERAGE(N96:N115)/(_xlfn.STDEV.S(N96:N115)/SQRT(COUNT(N96:N115))) -> 9.0550371 | N9: =COUNT(N96:N115)-1 -> 19
A10: Pooled (n = 100) | B10: =COUNT(H16:H115) -> 100 | C10: =AVERAGE(I16:I115) -> 0 | D10: =AVERAGE(K16:K115) -> 65 | E10: =AVERAGE(M16:M115) -> 63 | F10: =AVERAGE(J16:J115) -> 197.1611 | G10: =AVERAGE(L16:L115) -> 80.3417 | H10: =(F10-G10)/F10 -> 0.59250735 | I10: =_xlfn.STDEV.S(J16:J115) -> 70.87828 | J10: =_xlfn.STDEV.S(L16:L115) -> 41.805678 | K10: =TEXT(F10,"0.00")&" ± "&TEXT(I10,"0.0") -> 197.16 ± 70.9 | L10: =TEXT(G10,"0.00")&" ± "&TEXT(J10,"0.0") -> 80.34 ± 41.8 | M10: =AVERAGE(N16:N115)/(_xlfn.STDEV.S(N16:N115)/SQRT(COUNT(N16:N115))) -> 17.235018 | N10: =COUNT(N16:N115)-1 -> 99
A12: Catatan: angka sesudah ± di Table 9 adalah STANDAR DEVIASI sampel (STDEV.S), berbeda dengan Table 8 yang memakai margin of error CI 95%. Paired t = rata-rata selisih kolom N / (SD selisih / √n).
A14: DATA MENTAH 100 SAMPEL PENGUJIAN DIVERSE (PER-QUERY DETAIL DENGAN 5 STRATA)
A15: No | B15: Dimensi Diversitas | C15: Doc ID | D15: Kata Asli | E15: Kueri Typo | F15: Panjang | G15: Diagnosis Penyakit | H15: Waktu Exact (ms) | I15: Recall Exact | J15: Waktu N-Gram (ms) | K15: Recall N-Gram | L15: Waktu LSH (ms) | M15: Recall LSH | N15: Selisih N-Gram - LSH (ms)
A16: 1 | B16: Short Terms (4-6 chars) | C16: S82.3 | D16: lower | E16: loer | F16: 5 | G16: Fracture of lower end of tibia | H16: 2.17 | I16: 0 | J16: 213.47 | K16: 100 | L16: 284.47 | M16: 100 | N16: =J16-L16 -> -71
A17: 2 | B17: Short Terms (4-6 chars) | C17: S82.3 | D17: tibia | E17: tibqa | F17: 5 | G17: Fracture of lower end of tibia | H17: 2.05 | I17: 0 | J17: 155.9 | K17: 0 | L17: 67.55 | M17: 0 | N17: =J17-L17 -> 88.35
A18: 3 | B18: Short Terms (4-6 chars) | C18: S82.3 | D18: ujung | E18: ujng | F18: 5 | G18: Fracture of lower end of tibia | H18: 1.98 | I18: 0 | J18: 110.41 | K18: 100 | L18: 103.55 | M18: 100 | N18: =J18-L18 -> 6.86
A19: 4 | B19: Short Terms (4-6 chars) | C19: S82.3 | D19: bawah | E19: baah | F19: 5 | G19: Fracture of lower end of tibia | H19: 1.18 | I19: 0 | J19: 91.61 | K19: 100 | L19: 54.26 | M19: 100 | N19: =J19-L19 -> 37.35
A20: 5 | B20: Short Terms (4-6 chars) | C20: B40.9 | D20: tidak | E20: tidk | F20: 5 | G20: Blastomycosis, unspecified | H20: 1.42 | I20: 0 | J20: 165.36 | K20: 100 | L20: 57.84 | M20: 0 | N20: =J20-L20 -> 107.52
A21: 6 | B21: Short Terms (4-6 chars) | C21: T95.2 | D21: burn | E21: bun | F21: 4 | G21: Sequelae of burn, corrosion and frostbite of upper limb | H21: 1.71 | I21: 0 | J21: 161.95 | K21: 100 | L21: 16.47 | M21: 100 | N21: =J21-L21 -> 145.48
A22: 7 | B22: Short Terms (4-6 chars) | C22: T95.2 | D22: upper | E22: uper | F22: 5 | G22: Sequelae of burn, corrosion and frostbite of upper limb | H22: 1.12 | I22: 0 | J22: 192.52 | K22: 100 | L22: 112.43 | M22: 100 | N22: =J22-L22 -> 80.09
A23: 8 | B23: Short Terms (4-6 chars) | C23: T95.2 | D23: limb | E23: lib | F23: 4 | G23: Sequelae of burn, corrosion and frostbite of upper limb | H23: 1.61 | I23: 0 | J23: 77.33 | K23: 100 | L23: 20.52 | M23: 100 | N23: =J23-L23 -> 56.81
A24: 9 | B24: Short Terms (4-6 chars) | C24: T95.2 | D24: gejala | E24: gejlaa | F24: 6 | G24: Sequelae of burn, corrosion and frostbite of upper limb | H24: 1.44 | I24: 0 | J24: 149.26 | K24: 0 | L24: 14.57 | M24: 0 | N24: =J24-L24 -> 134.69
A25: 10 | B25: Short Terms (4-6 chars) | C25: T95.2 | D25: sisa | E25: ssa | F25: 4 | G25: Sequelae of burn, corrosion and frostbite of upper limb | H25: 1.01 | I25: 0 | J25: 131.27 | K25: 100 | L25: 5.61 | M25: 0 | N25: =J25-L25 -> 125.66
A26: 11 | B26: Short Terms (4-6 chars) | C26: T95.2 | D26: luka | E26: lkua | F26: 4 | G26: Sequelae of burn, corrosion and frostbite of upper limb | H26: 0.8 | I26: 0 | J26: 114.93 | K26: 0 | L26: 35.88 | M26: 0 | N26: =J26-L26 -> 79.05
A27: 12 | B27: Short Terms (4-6 chars) | C27: T95.2 | D27: bakar | E27: baakr | F27: 5 | G27: Sequelae of burn, corrosion and frostbite of upper limb | H27: 1.38 | I27: 0 | J27: 105.44 | K27: 0 | L27: 111.47 | M27: 0 | N27: =J27-L27 -> -6.03
... A115: 100 | B115: Phonetic/Orthographic Shifts | C115: R83.2 | D115: obatan | E115: obagan | F115: 6 | G115: Abnormal findings in cerebrospinal fluid, abnormal level of other drugs, medicaments and biological substances | H115: 1.41 | I115: 0 | J115: 265.29 | K115: 0 | L115: 79.34 | M115: 0 | N115: =J115-L115 -> 185.95

Sheet Master_Indeks_Overview
A1: TABLE 6 & FIGURE 5. MASTER INVERTED INDEX STORAGE OVERHEAD AFTER FULL ICD-10 CORPUS INGESTION
A2: Dataset Master: 10.469 Rekam Medis ICD-10 (Enkripsi AES-256-CBC Payload, Trapdoor HMAC-SHA256, 128 Bytes/Row Storage Density)
A4: Nama Tabel Database | B4: Skema Pengindeksan (Indexing Scheme) | C4: Total Baris Indeks | D4: Rasio Ekspansi vs Baseline | E4: Ukuran Memori Indeks (MB) | F4: Efisiensi Penyimpanan vs N-Gram (%) | G4: Keterangan Arsitektural
A5: icds_encrypted | B5: Dokumen Terenkripsi (Payload AES-256-CBC) | C5: 10469 | D5: N/A | E5: =(C5*512)/(1024*1024) -> 5.1118164 | F5: N/A | G5: Tabel penyimpanan ciphertext rekam medis pasien
A6: exact_index | B6: Exact Match (Baseline Deterministik) | C6: 110102 | D6: =C6/$C$6 -> 1 | E6: =(C6*128)/(1024*1024) -> 13.440186 | F6: N/A | G6: Pemetaan 1:1 kata per trapdoor, gagal total terhadap typo (0% recall)
A7: ngram_index | B7: N-Gram (Bi-gram Expansion, n = 2) | C7: 879327 | D7: =C7/$C$6 -> 7.9864762 | E7: =(C7*128)/(1024*1024) -> 107.33972 | F7: Baseline (0%) | G7: Toleran typo, namun memicu index bloat masif (~8x lipat dari baseline)
A8: lsh_index (k=3) | B8: LSH MinHash (Recommended, k = 3) | C8: 330306 | D8: =C8/$C$6 -> 3 | E8: =(C8*128)/(1024*1024) -> 40.320557 | F8: =(C$7-C8)/C$7 -> 0.624365 | G8: Ukuran konstan 3 band per kata: menghemat 62.4% baris vs N-Gram
A9: lsh_index (k=5) | B9: LSH MinHash (Extended, k = 5) | C9: 550510 | D9: =C9/$C$6 -> 5 | E9: =(C9*128)/(1024*1024) -> 67.200928 | F9: =(C$7-C9)/C$7 -> 0.37394166 | G9: Ukuran konstan 5 band per kata: menghemat 37.4% baris vs N-Gram

Sheet Panduan_Angka_PlusMinus
A1: PANDUAN ANGKA "±" DI NASKAH: ARTI, RUMUS, DAN ASAL DATA
A2: Setiap baris di bawah menunjuk ke sel sumber (formula hidup). Kolom "Cocok?" membandingkan teks hasil rumus dengan teks yang tercetak di naskah.
A4: Lokasi di naskah | B4: Skema / strata | C4: Teks di naskah | D4: Teks hasil rumus | E4: Cocok? | F4: Arti angka sesudah ± | G4: Rumus | H4: Contoh hitung | I4: Sel sumber
A5: Table 8 (hlm. 10) | B5: Exact Match | C5: 1.51 ± 0.07 | D5: ='Pengujian_100_Sampel'!G121 -> 1.51 ± 0.07 | E5: =IF(D5=C5,"YA","TIDAK") -> YA | F5: Margin of error interval kepercayaan 95% (BUKAN standar deviasi) | G5: MoE = t_crit × s / √n, t_crit = T.INV.2T(0,05; n−1) = 1,984 (df = 99) | H5: ="1,984 × "&TEXT('Pengujian_100_Sampel'!G108,"0.00")&" / √100 = "&TEXT('Pengujian_100_Sampel'!G111,"0.00") -> 1,984 × 0.37 / √100 = 0.07 | I5: 'Pengujian_100_Sampel'!G107 (mean), G108 (s), G111 (MoE)
A6: Table 8 (hlm. 10) | B6: N-Gram (θ = 0.40) | C6: 248.43 ± 13.13 | D6: ='Pengujian_100_Sampel'!L121 -> 248.43 ± 13.13 | E6: =IF(D6=C6,"YA","TIDAK") -> YA | F6: Margin of error interval kepercayaan 95% (BUKAN standar deviasi) | G6: MoE = t_crit × s / √n, t_crit = T.INV.2T(0,05; n−1) = 1,984 (df = 99) | H6: ="1,984 × "&TEXT('Pengujian_100_Sampel'!L108,"0.00")&" / √100 = "&TEXT('Pengujian_100_Sampel'!L111,"0.00") -> 1,984 × 66.20 / √100 = 13.13 | I6: 'Pengujian_100_Sampel'!L107, L108, L111
A7: Table 8 (hlm. 10) | B7: LSH (k = 3, τ = 85%) | C7: 74.58 ± 24.82 | D7: ='Pengujian_100_Sampel'!Q121 -> 74.58 ± 24.82 | E7: =IF(D7=C7,"YA","TIDAK") -> YA | F7: Margin of error interval kepercayaan 95% (BUKAN standar deviasi) | G7: MoE = t_crit × s / √n, t_crit = T.INV.2T(0,05; n−1) = 1,984 (df = 99) | H7: ="1,984 × "&TEXT('Pengujian_100_Sampel'!Q108,"0.00")&" / √100 = "&TEXT('Pengujian_100_Sampel'!Q111,"0.00") -> 1,984 × 125.09 / √100 = 24.82 | I7: 'Pengujian_100_Sampel'!Q107, Q108, Q111
A8: Table 9 (hlm. 12) | B8: Short Terms (4–6): N-Gram | C8: 151.87 ± 46.2 | D8: ='Diversitas_Kueri_Tabel9'!K5 -> 151.87 ± 46.2 | E8: =IF(D8=C8,"YA","TIDAK") -> YA | F8: Standar deviasi sampel s (BUKAN margin of error) | G8: s = STDEV.S(data latensi strata) | H8: ="s = "&TEXT('Diversitas_Kueri_Tabel9'!I5,"0.00") -> s = 46.23 | I8: 'Diversitas_Kueri_Tabel9'!F5 (mean), I5 (s)
A9: Table 9 (hlm. 12) | B9: Short Terms (4–6): LSH | C9: 81.26 ± 61.6 | D9: ='Diversitas_Kueri_Tabel9'!L5 -> 81.26 ± 61.6 | E9: =IF(D9=C9,"YA","TIDAK") -> YA | F9: Standar deviasi sampel s (BUKAN margin of error) | G9: s = STDEV.S(data latensi strata) | H9: ="s = "&TEXT('Diversitas_Kueri_Tabel9'!J5,"0.00") -> s = 61.56 | I9: 'Diversitas_Kueri_Tabel9'!G5 (mean), J5 (s)
A10: Table 9 (hlm. 12) | B10: Medium Terms (7–10): N-Gram | C10: 197.10 ± 67.1 | D10: ='Diversitas_Kueri_Tabel9'!K6 -> 197.10 ± 67.1 | E10: =IF(D10=C10,"YA","TIDAK") -> YA | F10: Standar deviasi sampel s (BUKAN margin of error) | G10: s = STDEV.S(data latensi strata) | H10: ="s = "&TEXT('Diversitas_Kueri_Tabel9'!I6,"0.00") -> s = 67.14 | I10: 'Diversitas_Kueri_Tabel9'!F6 (mean), I6 (s)
A11: Table 9 (hlm. 12) | B11: Medium Terms (7–10): LSH | C11: 81.30 ± 37.7 | D11: ='Diversitas_Kueri_Tabel9'!L6 -> 81.30 ± 37.7 | E11: =IF(D11=C11,"YA","TIDAK") -> YA | F11: Standar deviasi sampel s (BUKAN margin of error) | G11: s = STDEV.S(data latensi strata) | H11: ="s = "&TEXT('Diversitas_Kueri_Tabel9'!J6,"0.00") -> s = 37.71 | I11: 'Diversitas_Kueri_Tabel9'!G6 (mean), J6 (s)
A12: Table 9 (hlm. 12) | B12: Long Polysyllabic (≥ 11): N-Gram | C12: 252.58 ± 67.1 | D12: ='Diversitas_Kueri_Tabel9'!K7 -> 252.58 ± 67.1 | E12: =IF(D12=C12,"YA","TIDAK") -> YA | F12: Standar deviasi sampel s (BUKAN margin of error) | G12: s = STDEV.S(data latensi strata) | H12: ="s = "&TEXT('Diversitas_Kueri_Tabel9'!I7,"0.00") -> s = 67.07 | I12: 'Diversitas_Kueri_Tabel9'!F7 (mean), I7 (s)
A13: Table 9 (hlm. 12) | B13: Long Polysyllabic (≥ 11): LSH | C13: 79.43 ± 34.0 | D13: ='Diversitas_Kueri_Tabel9'!L7 -> 79.43 ± 34.0 | E13: =IF(D13=C13,"YA","TIDAK") -> YA | F13: Standar deviasi sampel s (BUKAN margin of error) | G13: s = STDEV.S(data latensi strata) | H13: ="s = "&TEXT('Diversitas_Kueri_Tabel9'!J7,"0.00") -> s = 33.98 | I13: 'Diversitas_Kueri_Tabel9'!G7 (mean), J7 (s)
A14: Table 9 (hlm. 12) | B14: Compound Typo (d = 2): N-Gram | C14: 182.85 ± 65.6 | D14: ='Diversitas_Kueri_Tabel9'!K8 -> 182.85 ± 65.6 | E14: =IF(D14=C14,"YA","TIDAK") -> YA | F14: Standar deviasi sampel s (BUKAN margin of error) | G14: s = STDEV.S(data latensi strata) | H14: ="s = "&TEXT('Diversitas_Kueri_Tabel9'!I8,"0.00") -> s = 65.65 | I14: 'Diversitas_Kueri_Tabel9'!F8 (mean), I8 (s)
A15: Table 9 (hlm. 12) | B15: Compound Typo (d = 2): LSH | C15: 73.36 ± 33.4 | D15: ='Diversitas_Kueri_Tabel9'!L8 -> 73.36 ± 33.4 | E15: =IF(D15=C15,"YA","TIDAK") -> YA | F15: Standar deviasi sampel s (BUKAN margin of error) | G15: s = STDEV.S(data latensi strata) | H15: ="s = "&TEXT('Diversitas_Kueri_Tabel9'!J8,"0.00") -> s = 33.44 | I15: 'Diversitas_Kueri_Tabel9'!G8 (mean), J8 (s)
A16: Table 9 (hlm. 12) | B16: Phonetic/Orthographic Shifts: N-Gram | C16: 201.40 ± 71.4 | D16: ='Diversitas_Kueri_Tabel9'!K9 -> 201.40 ± 71.4 | E16: =IF(D16=C16,"YA","TIDAK") -> YA | F16: Standar deviasi sampel s (BUKAN margin of error) | G16: s = STDEV.S(data latensi strata) | H16: ="s = "&TEXT('Diversitas_Kueri_Tabel9'!I9,"0.00") -> s = 71.39 | I16: 'Diversitas_Kueri_Tabel9'!F9 (mean), I9 (s)
A17: Table 9 (hlm. 12) | B17: Phonetic/Orthographic Shifts: LSH | C17: 86.35 ± 39.1 | D17: ='Diversitas_Kueri_Tabel9'!L9 -> 86.35 ± 39.1 | E17: =IF(D17=C17,"YA","TIDAK") -> YA | F17: Standar deviasi sampel s (BUKAN margin of error) | G17: s = STDEV.S(data latensi strata) | H17: ="s = "&TEXT('Diversitas_Kueri_Tabel9'!J9,"0.00") -> s = 39.13 | I17: 'Diversitas_Kueri_Tabel9'!G9 (mean), J9 (s)
A18: Table 9 (hlm. 12) | B18: Pooled (n = 100), juga di teks hlm. 12: N-Gram | C18: 197.16 ± 70.9 | D18: ='Diversitas_Kueri_Tabel9'!K10 -> 197.16 ± 70.9 | E18: =IF(D18=C18,"YA","TIDAK") -> YA | F18: Standar deviasi sampel s (BUKAN margin of error) | G18: s = STDEV.S(data latensi strata) | H18: ="s = "&TEXT('Diversitas_Kueri_Tabel9'!I10,"0.00") -> s = 70.88 | I18: 'Diversitas_Kueri_Tabel9'!F10 (mean), I10 (s)
A19: Table 9 (hlm. 12) | B19: Pooled (n = 100), juga di teks hlm. 12: LSH | C19: 80.34 ± 41.8 | D19: ='Diversitas_Kueri_Tabel9'!L10 -> 80.34 ± 41.8 | E19: =IF(D19=C19,"YA","TIDAK") -> YA | F19: Standar deviasi sampel s (BUKAN margin of error) | G19: s = STDEV.S(data latensi strata) | H19: ="s = "&TEXT('Diversitas_Kueri_Tabel9'!J10,"0.00") -> s = 41.81 | I19: 'Diversitas_Kueri_Tabel9'!G10 (mean), J10 (s)
A21: Catatan untuk naskah: kedua tabel memakai "±" dengan arti berbeda (Table 8 = margin of error 95%, Table 9 = standar deviasi). Sebaiknya arti "±" ditulis di caption masing-masing tabel.
A24: SKENARIO SENSITIVITAS: DAMPAK 2 LATENSI LSH NEGATIF (Table 7 & 8)
A25: Latensi tidak mungkin < 0. Dua nilai negatif berasal dari timer microtime() (jam dinding) yang mundur saat benchmark. Data mentah TIDAK diubah; skenario B hanya menghitung ulang dengan mengecualikan pasangan kueri yang LSH-nya < 0.
A27: Statistik | B27: A. Seperti di naskah (n = 100) | C27: B. Tanpa 2 nilai negatif (n = 98) | D27: Rumus skenario B
A28: Jumlah pasangan kueri (n) | B28: ='Pengujian_100_Sampel'!Q110 -> 100 | C28: =COUNTIF('Pengujian_100_Sampel'!Q3:Q102,">=0") -> 98 | D28: COUNTIF(LSH ≥ 0)
A29: Jumlah latensi LSH negatif | B29: ='Pengujian_100_Sampel'!Q123 -> 2 | C29: =0 -> 0 | D29: dikecualikan
A30: Mean LSH (ms) | B30: ='Pengujian_100_Sampel'!Q107 -> 74.5818 | C30: =AVERAGEIF('Pengujian_100_Sampel'!Q3:Q102,">=0") -> 91.212857 | D30: AVERAGEIF(LSH ≥ 0)
A31: SD LSH (ms) | B31: ='Pengujian_100_Sampel'!Q108 -> 125.09266 | C31: =SQRT(SUMPRODUCT(('Pengujian_100_Sampel'!Q3:Q102>=0)*('Pengujian_100_Sampel'!Q3:Q102-C30)^2)/(C28-1)) -> 41.92651 | D31: SD sampel hanya baris LSH ≥ 0
A32: t_crit (α = 0.05, df = n − 1) | B32: =_xlfn.T.INV.2T(0.05,B28-1) -> 1.984217 | C32: =_xlfn.T.INV.2T(0.05,C28-1) -> 1.9847232 | D32: T.INV.2T(0,05; n−1)
A33: Margin of error LSH (± Table 8) | B33: ='Pengujian_100_Sampel'!Q111 -> 24.818383 | C33: =C32*C31/SQRT(C28) -> 8.4057336 | D33: t_crit × s / √n
A34: Teks "Mean ± MoE" LSH | B34: ='Pengujian_100_Sampel'!Q121 -> 74.58 ± 24.82 | C34: =TEXT(C30,"0.00")&" ± "&TEXT(C33,"0.00") -> 91.21 ± 8.41
A35: Mean N-Gram pada pasangan yang sama (ms) | B35: ='Pengujian_100_Sampel'!L107 -> 248.4308 | C35: =_xlfn.AVERAGEIFS('Pengujian_100_Sampel'!L3:L102,'Pengujian_100_Sampel'!Q3:Q102,">=0") -> 248.84388 | D35: AVERAGEIFS(N-Gram; LSH ≥ 0)
A36: Penurunan latensi LSH vs N-Gram | B36: =1-B30/B35 -> 0.69978843 | C36: =1-C30/C35 -> 0.63345348 | D36: 1 − mean LSH / mean N-Gram
A37: Mean selisih berpasangan D̄ (ms) | B37: =AVERAGE('Pengujian_100_Sampel'!V3:V102) -> 173.849 | C37: =_xlfn.AVERAGEIFS('Pengujian_100_Sampel'!V3:V102,'Pengujian_100_Sampel'!Q3:Q102,">=0") -> 157.63102 | D37: selisih N-Gram − LSH
A38: SD selisih (ms) | B38: =_xlfn.STDEV.S('Pengujian_100_Sampel'!V3:V102) -> 129.55996 | C38: =SQRT(SUMPRODUCT(('Pengujian_100_Sampel'!Q3:Q102>=0)*('Pengujian_100_Sampel'!V3:V102-C37)^2)/(C28-1)) -> 61.745575
A39: Paired t | B39: ='Pengujian_100_Sampel'!L117 -> 13.41842 | C39: =C37/(C38/SQRT(C28)) -> 25.272539 | D39: D̄ / (SD selisih / √n)
A40: p-value (dua arah) | B40: =_xlfn.T.DIST.2T(B39,B28-1) -> 0 | C40: =_xlfn.T.DIST.2T(C39,C28-1) -> 0 | D40: T.DIST.2T(t; n−1)
A42: Kesimpulan statistik (LSH signifikan lebih cepat, p < 0,001) sama di kedua skenario; yang berubah adalah besarnya angka (mean, ±, persentase penurunan).
